Workbook

Sheet Icesi sin ADN 1-2-3 (cálculo me
A1: Periodo de ingreso - Estudiante | B1: No. Estudiantes | C1: No. Retirados Universidad | D1: No. Graduados Universidad | E1: Est. Activos Universidad | F1: % Retiro Universidad | G1: % Graduados Universidad | H1: % Activos Universidad
A2: 201910 | B2: 308 | C2: 43 | D2: 0 | E2: 265 | F2: 0.13961039 | G2: 0 | H2: 0.86038961
A3: 201920 | B3: 193 | C3: 30 | D3: 0 | E3: 163 | F3: 0.15544041 | G3: 0 | H3: 0.84455959
A4: 202010 | B4: 418 | C4: 28 | D4: 0 | E4: 390 | F4: 0.066985646 | G4: 0 | H4: 0.93301435
B6: 2021 | C6: 2022
B7: =((B2*F2)+(B3*F3))/(B2+B3) -> 0.14570858 | C7: =F4 -> 0.066985646

Sheet Icesi sin ADN (cálculo metas)
A1: Periodo de ingreso - Estudiante | B1: No. Estudiantes | C1: No. Retirados Universidad | D1: No. Graduados Universidad | E1: Est. Activos Universidad | F1: % Retiro Universidad | G1: % Graduados Universidad | H1: % Activos Universidad
A2: 197920 | B2: 40 | C2: 26 | D2: 14 | E2: 0 | F2: 0.65 | G2: 0.35 | H2: 0
A3: 198010 | B3: 5 | C3: 1 | D3: 4 | E3: 0 | F3: 0.2 | G3: 0.8 | H3: 0
A4: 198020 | B4: 37 | C4: 13 | D4: 24 | E4: 0 | F4: 0.35135135 | G4: 0.64864865 | H4: 0
A5: 198110 | B5: 4 | C5: 1 | D5: 3 | E5: 0 | F5: 0.25 | G5: 0.75 | H5: 0
A6: 198120 | B6: 41 | C6: 11 | D6: 30 | E6: 0 | F6: 0.26829268 | G6: 0.73170732 | H6: 0
A7: 198210 | B7: 40 | C7: 18 | D7: 22 | E7: 0 | F7: 0.45 | G7: 0.55 | H7: 0
A8: 198220 | B8: 50 | C8: 23 | D8: 27 | E8: 0 | F8: 0.46 | G8: 0.54 | H8: 0
A9: 198310 | B9: 42 | C9: 20 | D9: 22 | E9: 0 | F9: 0.47619048 | G9: 0.52380952 | H9: 0
A10: 198320 | B10: 57 | C10: 17 | D10: 40 | E10: 0 | F10: 0.29824561 | G10: 0.70175439 | H10: 0
A11: 198410 | B11: 109 | C11: 48 | D11: 61 | E11: 0 | F11: 0.44036697 | G11: 0.55963303 | H11: 0
A12: 198420 | B12: 142 | C12: 49 | D12: 93 | E12: 0 | F12: 0.34507042 | G12: 0.65492958 | H12: 0
A13: 198510 | B13: 121 | C13: 58 | D13: 63 | E13: 0 | F13: 0.47933884 | G13: 0.52066116 | H13: 0
... A84: 202020 | B84: 1 | C84: 0 | D84: 0 | E84: 1 | F84: 0 | G84: 0 | H84: 1
B86: 2021 | C86: 2022
B87: =((B82*F82)+(B83*F83))/(B82+B83) -> 0.1196984 | C87: =F84 -> 0

Sheet 1d. Retiro temprano.
B2: RETIRO TEMPRANO INSTITUCIONAL*
B3: Fecha de corte: grados 2024-2.
B4: * No incluye estudiantes de Administración Noctura ni estudiantes internacionales
B5: Periodo de ingreso - Estudiante | C5: No. Estudiantes al periodo de ingreso | D5: No. Retirados al iniciar el 4to semestre | E5: % Retiro al iniciar el 4to semestre | F5: No. Graduados al iniciar el 4to semestre | G5: % Graduados al iniciar el 4to semestre | H5: Est. Activos al iniciar 4to semestre | I5: % Activos de estudiantes activos al iniciar 4to semestre
B6: 201310 | C6: 477 | D6: 107 | E6: 0.22431866 | F6: 0 | G6: 0 | H6: 370 | I6: 0.77568134
B7: 201320 | C7: 580 | D7: 136 | E7: 0.23448276 | F7: 0 | G7: 0 | H7: 444 | I7: 0.76551724
B8: 201410 | C8: 475 | D8: 110 | E8: 0.232 | F8: 0 | G8: 0 | H8: 365 | I8: 0.768
B9: 201420 | C9: 739 | D9: 175 | E9: 0.237 | F9: 0 | G9: 0 | H9: 564 | I9: 0.763
B10: 201510 | C10: 838 | D10: 159 | E10: 0.19 | F10: 0 | G10: 0 | H10: 679 | I10: 0.81
B11: 201520 | C11: 591 | D11: 119 | E11: 0.20135364 | F11: 0 | G11: 0 | H11: 472 | I11: 0.79864636
B12: 201610 | C12: 985 | D12: 190 | E12: 0.1928934 | F12: 0 | G12: 0 | H12: 795 | I12: 0.8071066
B13: 201620 | C13: 669 | D13: 137 | E13: 0.20478326 | F13: 0 | G13: 0 | H13: 532 | I13: 0.79521674
B14: 201710 | C14: 812 | D14: 156 | E14: 0.19211823 | F14: 0 | G14: 0 | H14: 656 | I14: 0.80788177
B15: 201720 | C15: 619 | D15: 107 | E15: 0.17285945 | F15: 0 | G15: 0 | H15: 512 | I15: 0.82714055
B16: 201810 | C16: 647 | D16: 114 | E16: 0.17619784 | F16: 0 | G16: 0 | H16: 533 | I16: 0.82380216
B17: 201820 | C17: 570 | D17: 90 | E17: 0.15789474 | F17: 0 | G17: 0 | H17: 480 | I17: 0.84210526
... B23: 202120 | C23: 509 | D23: 70 | E23: 0.13752456 | F23: 0 | G23: 0 | H23: 439 | I23: 0.86247544
B24: 202210 | C24: 584 | D24: 70 | E24: =D24/C24 -> 0.11986301 | F24: 0 | G24: =F24/C24 -> 0 | H24: 514 | I24: =H24/C24 -> 0.88013699
B25: 202220 | C25: 641 | D25: 94 | E25: =D25/C25 -> 0.14664587 | F25: 0 | G25: =F25/C25 -> 0 | H25: 547 | I25: =H25/C25 -> 0.85335413
B26: 202310 | C26: 552 | D26: 77 | E26: =D26/C26 -> 0.13949275 | F26: 0 | G26: =F26/C26 -> 0 | H26: 475 | I26: =H26/C26 -> 0.86050725
C27: =SUM(C6:C26) -> 12824 | D27: =SUM(D6:D26) -> 2244 | E27: =D27/C27 -> 0.1749844
B28: Indicador institucional - 1d. Retiro temprano % de retiro de las cohortes con 3 semestres de estudio calculado en una ventana de 1 año
B29: Promedio ponderado con MED y sin ADN
B30: **2014 122-131 | C30: 2015 132-141 | D30: 2016 142-151 | E30: 2017 152-161 | F30: 2018 162-171 | G30: 2019 172-181 | H30: 2020 182-191 | I30: 2021 192-201 | J30: 2022 202-211 | K30: 2023 212-221 | L30: 2024-1*** 222
B31: =+E6 -> 0.22431866 | C31: =+((C7*E7)+(C8*E8))/(C7+C8) -> 0.23336493 | D31: =+((C9*E9)+(C10*E10))/(C9+C10) -> 0.21202473 | E31: =+((C11*E11)+(C12*E12))/(C11+C12) -> 0.19606599 | F31: =+((C13*E13)+(C14*E14))/(C13+C14) -> 0.1978393 | G31: =((C15*E15)+(C16*E16))/(C15+C16) -> 0.17456556 | H31: =((C17*E17)+(C18*E18))/(C17+C18) -> 0.16216216 | I31: =((C19*E19)+(C20*E20))/(C19+C20) -> 0.13867925 | J31: =((C21*E21)+(C22*E22))/(C21+C22) -> 0.10694574 | K31: =(D23+D24)/(C23+C24) -> 0.12808783 | L31: =E25 -> 0.14664587
B32: ** para el ano 2014 solo se tomó el porcentaje de retiro del periodo 131 porque no se contaba con el porcentaje del periodo 122
B33: ***Para el periodo 2024-1 sólo se tomo el procentaje de 202220 que a esa fecha de medición cumple 3 semestres de estudio cursado y están en su cuarto semestre.

Sheet 3c.Retiro temprano 1, 2 y 3 
B2: RETIRO TEMPRANO INSTITUCIONAL (Estratos 1, 2 y 3)*
B3: Fecha de corte: grados 2024-2.
B4: * No incluye estudiantes de Administración Noctura ni estudiantes internacionales
B5: Periodo de ingreso - Estudiante | C5: No. Estudiantes al periodo de ingreso | D5: No. Retirados al iniciar el 4to semestre | E5: % Retiro al iniciar el 4to semestre | F5: No. Graduados al iniciar el 4to semestre | G5: % Graduados al iniciar el 4to semestre | H5: Est. Activos al iniciar 4to semestre | I5: % Activos de estudiantes activos al iniciar 4to semestre
B6: 201310 | C6: 340 | D6: 68 | E6: 0.2 | F6: 0 | G6: 0 | H6: 272 | I6: 0.8
B7: 201320 | C7: 277 | D7: 68 | E7: 0.24548736 | F7: 0 | G7: 0 | H7: 209 | I7: 0.75451264
B8: 201410 | C8: 329 | D8: 67 | E8: 0.204 | F8: 0 | G8: 0 | H8: 262 | I8: 0.796
B9: 201420 | C9: 351 | D9: 82 | E9: 0.23361823 | F9: 0 | G9: 0 | H9: 269 | I9: 0.76638177
B10: 201510 | C10: 685 | D10: 124 | E10: 0.1810219 | F10: 0 | G10: 0 | H10: 561 | I10: 0.8189781
B11: 201520 | C11: 267 | D11: 59 | E11: 0.22097378 | F11: 0 | G11: 0 | H11: 208 | I11: 0.77902622
B12: 201610 | C12: 812 | D12: 145 | E12: 0.17857143 | F12: 0 | G12: 0 | H12: 667 | I12: 0.82142857
B13: 201620 | C13: 282 | D13: 60 | E13: 0.21276596 | F13: 0 | G13: 0 | H13: 222 | I13: 0.78723404
B14: 201710 | C14: 634 | D14: 110 | E14: 0.17350158 | F14: 0 | G14: 0 | H14: 524 | I14: 0.82649842
B15: 201720 | C15: 247 | D15: 35 | E15: 0.1417004 | F15: 0 | G15: 0 | H15: 212 | I15: 0.8582996
B16: 201810 | C16: 444 | D16: 72 | E16: 0.16216216 | F16: 0 | G16: 0 | H16: 372 | I16: 0.83783784
B17: 201820 | C17: 218 | D17: 44 | E17: 0.20183486 | F17: 0 | G17: 0 | H17: 174 | I17: 0.79816514
... B23: 202120 | C23: 250 | D23: 27 | E23: 0.108 | F23: 0 | G23: 0 | H23: 223 | I23: 0.892
B24: 202210 | C24: =IF(RIGHT($B24,2)="10",_xlfn.XLOOKUP(TEXT($B24,"@"),'[1]ICESI SIN ADN 123'!$A:$A,'[1]ICESI SIN ADN 123'!B:B,0),_xlfn.XLOOKUP(TEXT($B24,"@"),'[2]ICESI SIN ADN 123'!$A:$A,'[2]ICESI SIN ADN 123'!B:B,0)) -> 421 | D24: =IF(RIGHT($B24,2)="10",_xlfn.XLOOKUP(TEXT($B24,"@"),'[1]ICESI SIN ADN 123'!$A:$A,'[1]ICESI SIN ADN 123'!C:C,0),_xlfn.XLOOKUP(TEXT($B24,"@"),'[2]ICESI SIN ADN 123'!$A:$A,'[2]ICESI SIN ADN 123'!C:C,0)) -> 37 | E24: =IFERROR(D24/C24,0) -> 0.087885986 | F24: =IF(RIGHT($B24,2)="10",_xlfn.XLOOKUP(TEXT($B24,"@"),'[1]ICESI SIN ADN 123'!$A:$A,'[1]ICESI SIN ADN 123'!D:D,0),_xlfn.XLOOKUP(TEXT($B24,"@"),'[2]ICESI SIN ADN 123'!$A:$A,'[2]ICESI SIN ADN 123'!D:D,0)) -> 0 | G24: =IFERROR(F24/C24,0) -> 0 | H24: =C24-D24 -> 384 | I24: =IFERROR(H24/C24,0) -> 0.91211401
B25: 202220 | C25: =IF(RIGHT($B25,2)="10",_xlfn.XLOOKUP(TEXT($B25,"@"),'[1]ICESI SIN ADN 123'!$A:$A,'[1]ICESI SIN ADN 123'!B:B,0),_xlfn.XLOOKUP(TEXT($B25,"@"),'[2]ICESI SIN ADN 123'!$A:$A,'[2]ICESI SIN ADN 123'!B:B,0)) -> 357 | D25: =IF(RIGHT($B25,2)="10",_xlfn.XLOOKUP(TEXT($B25,"@"),'[1]ICESI SIN ADN 123'!$A:$A,'[1]ICESI SIN ADN 123'!C:C,0),_xlfn.XLOOKUP(TEXT($B25,"@"),'[2]ICESI SIN ADN 123'!$A:$A,'[2]ICESI SIN ADN 123'!C:C,0)) -> 52 | E25: =IFERROR(D25/C25,0) -> 0.14565826 | F25: =IF(RIGHT($B25,2)="10",_xlfn.XLOOKUP(TEXT($B25,"@"),'[1]ICESI SIN ADN 123'!$A:$A,'[1]ICESI SIN ADN 123'!D:D,0),_xlfn.XLOOKUP(TEXT($B25,"@"),'[2]ICESI SIN ADN 123'!$A:$A,'[2]ICESI SIN ADN 123'!D:D,0)) -> 0 | G25: =IFERROR(F25/C25,0) -> 0 | H25: =C25-D25 -> 305 | I25: =IFERROR(H25/C25,0) -> 0.85434174
B26: 202310 | C26: 393 | D26: 55 | E26: =IFERROR(D26/C26,0) -> 0.13994911 | F26: 0 | G26: =IFERROR(F26/C26,0) -> 0 | H26: 338 | I26: =IFERROR(H26/C26,0) -> 0.86005089
B28: Indicador institucional - 3b. Retiro temprano 1, 2 y 3 % de retiro de las cohortes con 3 semestres de estudio calculado en una ventana de 1 año
B29: Promedio ponderado con MED y sin ADN
B30: **2014 122-131 | C30: 2015 132-141 | D30: 2016 142-151 | E30: 2017 152-161 | F30: 2018 162-171 | G30: 2019 172-181 | H30: 2020 182-191 | I30: 2021 192-201 | J30: 2022 202-211 | K30: ='1d. Retiro temprano.'!K30 -> 2023 212-221 | L30: 2024-1*** 222
B31: =+E6 -> 0.2 | C31: =((C7*E7)+(C8*E8))/(C7+C8) -> 0.2229637 | D31: =((C9*E9)+(C10*E10))/(C9+C10) -> 0.1988417 | E31: =((C11*E11)+(C12*E12))/(C11+C12) -> 0.18906395 | F31: =((C13*E13)+(C14*E14))/(C13+C14) -> 0.18558952 | G31: =((C15*E15)+(C16*E16))/(C15+C16) -> 0.15484805 | H31: =((C17*E17)+(C18*E18))/(C17+C18) -> 0.16539924 | I31: =((C19*E19)+(C20*E20))/(C19+C20) -> 0.10656443 | J31: =((C21*E21)+(C22*E22))/(C21+C22) -> 0.083333333 | K31: =(D23+D24)/(C23+C24) -> 0.09538003 | L31: =E25 -> 0.14565826
B32: ** para el ano 2014 solo se tomó el porcentaje de retiro del periodo 131 porque no se contaba con el porcentaje del periodo 122
B33: ***Para el periodo 2024-1 sólo se tomo el procentaje de 202220 que a esa fecha de medición cumple 3 semestres de estudio cursado y están en su cuarto semestre.

Sheet FNE
A1: Fecha de corte: grados 2024-2. | M1: Fecha de corte: grados 2024-2.
A3: RETIRO TEMPRANO FCAE | M3: RETIRO TEMPRANO FCAE-ESTRATOS 1,2 Y 3
A4: Periodo de ingreso - Estudiante | B4: No. Estudiantes al periodo de ingreso | C4: No. Retirados al iniciar el 4to semestre | D4: % Retiro al iniciar el 4to semestre | E4: No. Graduados al iniciar el 4to semestre | F4: % Graduados al iniciar el 4to semestre | G4: Est. Activos al iniciar 4to semestre | H4: % Activos de estudiantes activos al iniciar 4to semestre | M4: Periodo de ingreso - Estudiante | N4: No. Estudiantes al periodo de ingreso | O4: No. Retirados al iniciar el 4to semestre | P4: % Retiro al iniciar el 4to semestre | Q4: No. Graduados al iniciar el 4to semestre | R4: % Graduados al iniciar el 4to semestre | S4: Est. Activos al iniciar 4to semestre | T4: % Activos de estudiantes activos al iniciar 4to semestre
A5: 201310 | B5: 212 | C5: 48 | D5: =C5/B5 -> 0.22641509 | E5: 0 | F5: =E5/B5 -> 0 | G5: 164 | H5: =G5/B5 -> 0.77358491 | M5: 201310 | N5: 89 | O5: 16 | P5: =O5/N5 -> 0.17977528 | Q5: 0 | R5: =Q5/N5 -> 0 | S5: 73 | T5: =S5/N5 -> 0.82022472
A6: 201320 | B6: 212 | C6: 52 | D6: =C6/B6 -> 0.24528302 | E6: 0 | F6: =E6/B6 -> 0 | G6: 160 | H6: =G6/B6 -> 0.75471698 | M6: 201320 | N6: 89 | O6: 19 | P6: =O6/N6 -> 0.21348315 | Q6: 0 | R6: =Q6/N6 -> 0 | S6: 70 | T6: =S6/N6 -> 0.78651685
A7: 201410 | B7: 148 | C7: 33 | D7: =C7/B7 -> 0.22297297 | E7: 0 | F7: =E7/B7 -> 0 | G7: 115 | H7: =G7/B7 -> 0.77702703 | M7: 201410 | N7: 91 | O7: 15 | P7: =O7/N7 -> 0.16483516 | Q7: 0 | R7: =Q7/N7 -> 0 | S7: 76 | T7: =S7/N7 -> 0.83516484
A8: 201420 | B8: 285 | C8: 73 | D8: =C8/B8 -> 0.25614035 | E8: 0 | F8: =E8/B8 -> 0 | G8: 212 | H8: =G8/B8 -> 0.74385965 | M8: 201420 | N8: 100 | O8: 23 | P8: =O8/N8 -> 0.23 | Q8: 0 | R8: =Q8/N8 -> 0 | S8: 77 | T8: =S8/N8 -> 0.77
A9: 201510 | B9: 242 | C9: 49 | D9: =C9/B9 -> 0.20247934 | E9: 0 | F9: =E9/B9 -> 0 | G9: 193 | H9: =G9/B9 -> 0.79752066 | M9: 201510 | N9: 172 | O9: 31 | P9: =O9/N9 -> 0.18023256 | Q9: 0 | R9: =Q9/N9 -> 0 | S9: 141 | T9: =S9/N9 -> 0.81976744
A10: 201520 | B10: 201 | C10: 39 | D10: =C10/B10 -> 0.19402985 | E10: 0 | F10: =E10/B10 -> 0 | G10: 162 | H10: =G10/B10 -> 0.80597015 | M10: 201520 | N10: 78 | O10: 13 | P10: =O10/N10 -> 0.16666667 | Q10: 0 | R10: =Q10/N10 -> 0 | S10: 65 | T10: =S10/N10 -> 0.83333333
A11: 201610 | B11: 301 | C11: 78 | D11: =C11/B11 -> 0.25913621 | E11: 0 | F11: =E11/B11 -> 0 | G11: 223 | H11: =G11/B11 -> 0.74086379 | M11: 201610 | N11: 207 | O11: 51 | P11: =O11/N11 -> 0.24637681 | Q11: 0 | R11: =Q11/N11 -> 0 | S11: 156 | T11: =S11/N11 -> 0.75362319
A12: 201620 | B12: 329 | C12: 80 | D12: =C12/B12 -> 0.24316109 | E12: 3 | F12: =E12/B12 -> 0.009118541 | G12: 246 | H12: =G12/B12 -> 0.74772036 | M12: 201620 | N12: 134 | O12: 47 | P12: =O12/N12 -> 0.35074627 | Q12: 2 | R12: =Q12/N12 -> 0.014925373 | S12: 85 | T12: =S12/N12 -> 0.63432836
A13: 201710 | B13: 216 | C13: 45 | D13: =C13/B13 -> 0.20833333 | E13: 0 | F13: =E13/B13 -> 0 | G13: 171 | H13: =G13/B13 -> 0.79166667 | M13: 201710 | N13: 148 | O13: 30 | P13: =O13/N13 -> 0.2027027 | Q13: 0 | R13: =Q13/N13 -> 0 | S13: 118 | T13: =S13/N13 -> 0.7972973
A14: 201720 | B14: 240 | C14: 43 | D14: =C14/B14 -> 0.17916667 | E14: 0 | F14: =E14/B14 -> 0 | G14: 197 | H14: =G14/B14 -> 0.82083333 | M14: 201720 | N14: 88 | O14: 13 | P14: =O14/N14 -> 0.14772727 | Q14: 0 | R14: =Q14/N14 -> 0 | S14: 75 | T14: =S14/N14 -> 0.85227273
A15: 201810 | B15: 206 | C15: 36 | D15: =C15/B15 -> 0.17475728 | E15: 0 | F15: =E15/B15 -> 0 | G15: 170 | H15: =G15/B15 -> 0.82524272 | M15: 201810 | N15: 102 | O15: 19 | P15: =O15/N15 -> 0.18627451 | Q15: 0 | R15: =Q15/N15 -> 0 | S15: 83 | T15: =S15/N15 -> 0.81372549
A16: 201820 | B16: 202 | C16: 39 | D16: =C16/B16 -> 0.19306931 | E16: 0 | F16: =E16/B16 -> 0 | G16: 163 | H16: =G16/B16 -> 0.80693069 | M16: 201820 | N16: 74 | O16: 16 | P16: =O16/N16 -> 0.21621622 | Q16: 0 | R16: =Q16/N16 -> 0 | S16: 58 | T16: =S16/N16 -> 0.78378378
... A21: 202110 | B21: 162 | C21: 18 | D21: =C21/B21 -> 0.11111111 | E21: 0 | F21: =E21/B21 -> 0 | G21: 144 | H21: =G21/B21 -> 0.88888889 | M21: 202110 | N21: 78 | O21: 7 | P21: =O21/N21 -> 0.08974359 | Q21: 0 | R21: =Q21/N21 -> 0 | S21: 71 | T21: =S21/N21 -> 0.91025641
A22: 202120 | B22: 142 | C22: 29 | D22: 0.20422535 | E22: 0 | F22: 0 | G22: 113 | H22: 0.79577465 | M22: 202120 | N22: 60 | O22: 12 | P22: 0.2 | Q22: 0 | R22: 0 | S22: 48 | T22: 0.8
A23: 202210 | B23: =IF(RIGHT($A23,2)="10",_xlfn.XLOOKUP($A23,[1]FCAE!$B:$B,[1]FCAE!C:C,0),_xlfn.XLOOKUP($A23,[2]FCAE!$K:$K,[2]FCAE!L:L,0)) -> 294 | C23: =IF(RIGHT($A23,2)="10",_xlfn.XLOOKUP($A23,[1]FCAE!$B:$B,[1]FCAE!D:D,0),_xlfn.XLOOKUP($A23,[2]FCAE!$K:$K,[2]FCAE!M:M,0)) -> 49 | D23: =IFERROR(C23/B23,0) -> 0.16666667 | E23: =IF(RIGHT($A23,2)="10",_xlfn.XLOOKUP($A23,[1]FCAE!$B:$B,[1]FCAE!F:F,0),_xlfn.XLOOKUP($A23,[2]FCAE!$K:$K,[2]FCAE!O:O,0)) -> 0 | F23: =IFERROR(E23/B23,0) -> 0 | G23: =B23-C23 -> 245 | H23: =IFERROR(G23/B23,0) -> 0.83333333 | M23: 202210 | N23: =IF(RIGHT($A23,2)="10",_xlfn.XLOOKUP($A23,'[1]FCAE 123'!$B:$B,'[1]FCAE 123'!C:C,0),_xlfn.XLOOKUP($A23,'[2]FCAE 123'!$K:$K,'[2]FCAE 123'!L:L,0)) -> 159 | O23: =IF(RIGHT($A23,2)="10",_xlfn.XLOOKUP($A23,'[1]FCAE 123'!$B:$B,'[1]FCAE 123'!D:D,0),_xlfn.XLOOKUP($A23,'[2]FCAE 123'!$K:$K,'[2]FCAE 123'!M:M,0)) -> 24 | P23: =IFERROR(O23/N23,0) -> 0.1509434 | Q23: =IF(RIGHT($A23,2)="10",_xlfn.XLOOKUP($A23,'[1]FCAE 123'!$B:$B,'[1]FCAE 123'!F:F,0),_xlfn.XLOOKUP($A23,'[2]FCAE 123'!$K:$K,'[2]FCAE 123'!O:O,0)) -> 0 | R23: =IFERROR(Q23/N23,0) -> 0 | S23: =N23-O23 -> 135 | T23: =IFERROR(S23/N23,0) -> 0.8490566
A24: 202220 | B24: =IF(RIGHT($A24,2)="10",_xlfn.XLOOKUP($A24,[1]FCAE!$B:$B,[1]FCAE!C:C,0),_xlfn.XLOOKUP($A24,[2]FCAE!$K:$K,[2]FCAE!L:L,0)) -> 175 | C24: =IF(RIGHT($A24,2)="10",_xlfn.XLOOKUP($A24,[1]FCAE!$B:$B,[1]FCAE!D:D,0),_xlfn.XLOOKUP($A24,[2]FCAE!$K:$K,[2]FCAE!M:M,0)) -> 40 | D24: =IFERROR(C24/B24,0) -> 0.22857143 | E24: =IF(RIGHT($A24,2)="10",_xlfn.XLOOKUP($A24,[1]FCAE!$B:$B,[1]FCAE!F:F,0),_xlfn.XLOOKUP($A24,[2]FCAE!$K:$K,[2]FCAE!O:O,0)) -> 0 | F24: =IFERROR(E24/B24,0) -> 0 | G24: =B24-C24 -> 135 | H24: =IFERROR(G24/B24,0) -> 0.77142857 | M24: 202220 | N24: =IF(RIGHT($A24,2)="10",_xlfn.XLOOKUP($A24,'[1]FCAE 123'!$B:$B,'[1]FCAE 123'!C:C,0),_xlfn.XLOOKUP($A24,'[2]FCAE 123'!$K:$K,'[2]FCAE 123'!L:L,0)) -> 97 | O24: =IF(RIGHT($A24,2)="10",_xlfn.XLOOKUP($A24,'[1]FCAE 123'!$B:$B,'[1]FCAE 123'!D:D,0),_xlfn.XLOOKUP($A24,'[2]FCAE 123'!$K:$K,'[2]FCAE 123'!M:M,0)) -> 20 | P24: =IFERROR(O24/N24,0) -> 0.20618557 | Q24: =IF(RIGHT($A24,2)="10",_xlfn.XLOOKUP($A24,'[1]FCAE 123'!$B:$B,'[1]FCAE 123'!F:F,0),_xlfn.XLOOKUP($A24,'[2]FCAE 123'!$K:$K,'[2]FCAE 123'!O:O,0)) -> 0 | R24: =IFERROR(Q24/N24,0) -> 0 | S24: =N24-O24 -> 77 | T24: =IFERROR(S24/N24,0) -> 0.79381443
A25: 202310 | B25: 179 | C25: 28 | D25: =IFERROR(C25/B25,0) -> 0.15642458 | E25: 0 | F25: =IFERROR(E25/B25,0) -> 0 | G25: 151 | H25: =IFERROR(G25/B25,0) -> 0.84357542 | M25: 202310 | N25: 104 | O25: 20 | P25: =IFERROR(O25/N25,0) -> 0.19230769 | Q25: 0 | R25: =IFERROR(Q25/N25,0) -> 0 | S25: 84 | T25: =IFERROR(S25/N25,0) -> 0.80769231
A27: Indicador institucional - 1d. Retiro temprano % de retiro de las cohortes con 3 semestres de estudio calculado en una ventana de 1 año | M27: Indicador institucional - 3b. Retiro temprano 1, 2 y 3 % de retiro de las cohortes con 3 semestres de estudio calculado en una ventana de 1 año
A28: *2014 122-131 | B28: 2015 132-141 | C28: 2016 142-151 | D28: 2017 152-161 | E28: 2018 162-171 | F28: 2019 172-181 | G28: 2020 182-191 | H28: 2021 192-201 | I28: 2022 202-211 | J28: ='1d. Retiro temprano.'!K30 -> 2023 212-221 | K28: ='1d. Retiro temprano.'!L30 -> 2024-1*** 222 | M28: *2014 122-131 | N28: 2015 132-141 | O28: 2016 142-151 | P28: 2017 152-161 | Q28: 2018 162-171 | R28: 2019 172-181 | S28: 2020 182-191 | T28: 2021 192-201 | U28: 2022 202-211 | V28: =J28 -> 2023 212-221 | W28: =K28 -> 2024-1*** 222
A29: =D5 -> 0.22641509 | B29: =+((B6*D6)+(B7*D7))/(B6+B7) -> 0.23611111 | C29: =((B8*D8)+(B9*D9))/(B8+B9) -> 0.23149905 | D29: =+((B10*D10)+(B11*D11))/(B10+B11) -> 0.23306773 | E29: =((B12*D12)+(B13*D13))/(B12+B13) -> 0.2293578 | F29: =((B14*D14)+(B15*D15))/(B14+B15) -> 0.17713004 | G29: =((B16*D16)+(B17*D17))/(B16+B17) -> 0.20418848 | H29: =((B18*D18)+(B19*D19))/(B18+B19) -> 0.13612565 | I29: =((B20*D20)+(B21*D21))/(B20+B21) -> 0.11267606 | J29: =(C22+C23)/(B22+B23) -> 0.17889908 | K29: =D24 -> 0.22857143 | M29: =P5 -> 0.17977528 | N29: =+((N6*P6)+(N7*P7))/(N6+N7) -> 0.18888889 | O29: =((N8*P8)+(N9*P9))/(N8+N9) -> 0.19852941 | P29: =+((N10*P10)+(N11*P11))/(N10+N11) -> 0.2245614 | Q29: =((N12*P12)+(N13*P13))/(N12+N13) -> 0.27304965 | R29: =((N14*P14)+(N15*P15))/(N14+N15) -> 0.16842105 | S29: =((N16*P16)+(N17*P17))/(N16+N17) -> 0.18125 | T29: =((N18*P18)+(N19*P19))/(N18+N19) -> 0.13605442 | U29: =((N20*P20)+(N21*P21))/(N20+N21) -> 0.090909091 | V29: =(O22+O23)/(N22+N23) -> 0.16438356 | W29: =P24 -> 0.20618557
A30: * para el año 2014 solo se tomó el porcentaje de retiro del periodo 131 porque no se contaba con el porcentaje del periodo 122 | M30: * para el año 2014 solo se tomó el porcentaje de retiro del periodo 131 porque no se contaba con el porcentaje del periodo 122
A31: ** Para el periodo 2024-1 sólo se tomo el procentaje de 202220 que a esa fecha de medición cumple 3 semestres de estudio cursado y están en su cuarto semestre. | M31: ** Para el periodo 2024-1 sólo se tomo el procentaje de 202220 que a esa fecha de medición cumple 3 semestres de estudio cursado y están en su cuarto semestre.

Sheet EA
B1: Fecha de actualización: marzo de 2022 | K1: Fecha de actualización: marzo de 2022
B2: RETIRO TEMPRANO ESCUELA DE ADMINISTRACIÓN (FCAE) | K2: RETIRO TEMPRANO ESCUELA DE ADMINISTRACIÓN (FCAE)
B3: Periodo de ingreso - Estudiante | C3: No. Estudiantes al periodo de ingreso | D3: No. Retirados al iniciar el 4to semestre | E3: % Retiro al iniciar el 4to semestre | F3: No. Graduados al iniciar el 4to semestre | G3: % Graduados al iniciar el 4to semestre | H3: Est. Activos al iniciar 4to semestre | I3: % Activos de estudiantes activos al iniciar 4to semestre | K3: Periodo de ingreso - Estudiante | L3: No. Estudiantes al periodo de ingreso | M3: No. Retirados al iniciar el 4to semestre | N3: % Retiro al iniciar el 4to semestre | O3: No. Graduados al iniciar el 4to semestre | P3: % Graduados al iniciar el 4to semestre | Q3: Est. Activos al iniciar 4to semestre | R3: % Activos de estudiantes activos al iniciar 4to semestre
B4: 201820 | C4: 133 | D4: 23 | E4: 0.17293233 | F4: 0 | G4: 0 | H4: 110 | I4: 0.82706767 | K4: 201820 | L4: 46 | M4: 11 | N4: 0.23913043 | O4: 0 | P4: 0 | Q4: 35 | R4: 0.76086957
B5: 201910 | C5: 102 | D5: 29 | E5: 0.28431373 | F5: 0 | G5: 0 | H5: 73 | I5: 0.71568627 | K5: 201910 | L5: 35 | M5: 9 | N5: 0.25714286 | O5: 0 | P5: 0 | Q5: 26 | R5: 0.74285714
B6: 201920 | C6: 126 | D6: 21 | E6: 0.1667 | F6: 0 | G6: 0 | H6: 105 | I6: 0.8333 | K6: 201920 | L6: 39 | M6: 6 | N6: 0.1538 | O6: 0 | P6: 0 | Q6: 33 | R6: 0.8462
B7: 202010 | C7: 100 | D7: 13 | E7: 0.13 | F7: 0 | G7: 0 | H7: 87 | I7: 0.87 | K7: 202010 | L7: 30 | M7: 5 | N7: 0.16666667 | O7: 0 | P7: 0 | Q7: 25 | R7: 0.83333333
B9: Indicador institucional - 1d. Retiro temprano % de retiro de las cohortes con 3 semestres de estudio calculado en una ventana de 1 año | K9: Indicador institucional - 3b. Retiro temprano 1, 2 y 3 % de retiro de las cohortes con 3 semestres de estudio calculado en una ventana de 1 año
B10: 2014 122-131 | C10: 2015 132-141 | D10: 2016 142-151 | E10: 2017 152-161 | F10: 2018 162-171 | G10: 2019 172-181 | H10: **2020 182-191 | I10: 2021 192-201 | K10: 2014 122-131 | L10: 2015 132-141 | M10: 2016 142-151 | N10: 2017 152-161 | O10: 2018 162-171 | P10: 2019 172-181 | Q10: **2020 182-191 | R10: 2021 192-201
B11: - | C11: - | D11: - | E11: - | F11: - | G11: - | H11: =((C4*E4)+(C5*E5))/(C4+C5) -> 0.2212766 | I11: =((C6*E6)+(C7*E7))/(C6+C7) -> 0.15046106 | K11: - | L11: - | M11: - | N11: - | O11: - | P11: - | Q11: =((L4*N4)+(L5*N5))/(L4+L5) -> 0.24691358 | R11: =((L6*N6)+(L7*N7))/(L6+L7) -> 0.1593942
B12: ** la desagregación a nivel de escuelas se empieza a realizar desde el 2020-1, pues las escuelas nacieron en el 2019. | K12: ** la desagregación a nivel de escuelas se empieza a realizar desde el 2020-1, pues las escuelas nacieron en el 2019.
B13: La Escuela de Administración contiene los programas de Administración de Empresas (diurna y nocturna) y Mercadeo y Publicidad Internacional. | K13: La Escuela de Administración contiene los programas de Administración de Empresas (diurna y nocturna) y Mercadeo y Publicidad Internacional.

Sheet EE
B1: Fecha de actualización: marzo de 2022 | K1: Fecha de actualización: marzo de 2022
B2: RETIRO TEMPRANO ESCUELA DE ECONOMÍA (FCAE) | K2: RETIRO TEMPRANO ESCUELA DE ECONOMÍA (FCAE)
B3: Periodo de ingreso - Estudiante | C3: No. Estudiantes al periodo de ingreso | D3: No. Retirados al iniciar el 4to semestre | E3: % Retiro al iniciar el 4to semestre | F3: No. Graduados al iniciar el 4to semestre | G3: % Graduados al iniciar el 4to semestre | H3: Est. Activos al iniciar 4to semestre | I3: % Activos de estudiantes activos al iniciar 4to semestre | K3: Periodo de ingreso - Estudiante | L3: No. Estudiantes al periodo de ingreso | M3: No. Retirados al iniciar el 4to semestre | N3: % Retiro al iniciar el 4to semestre | O3: No. Graduados al iniciar el 4to semestre | P3: % Graduados al iniciar el 4to semestre | Q3: Est. Activos al iniciar 4to semestre | R3: % Activos de estudiantes activos al iniciar 4to semestre
B4: 201820 | C4: 69 | D4: 18 | E4: 0.26086957 | F4: 0 | G4: 0 | H4: 51 | I4: 0.73913043 | K4: 201820 | L4: 28 | M4: 5 | N4: 0.17857143 | O4: 0 | P4: 0 | Q4: 23 | R4: 0.82142857
B5: 201910 | C5: 78 | D5: 11 | E5: 0.14102564 | F5: 0 | G5: 0 | H5: 67 | I5: 0.85897436 | K5: 201910 | L5: 51 | M5: 4 | N5: 0.078431373 | O5: 0 | P5: 0 | Q5: 47 | R5: 0.92156863
B6: 201920 | C6: 84 | D6: 18 | E6: 0.2143 | F6: 0 | G6: 0 | H6: 66 | I6: 0.7857 | K6: 201920 | L6: 30 | M6: 6 | N6: 0.2 | O6: 0 | P6: 0 | Q6: 24 | R6: 0.8
B7: 202010 | C7: 80 | D7: 14 | E7: 0.175 | F7: 0 | G7: 0 | H7: 66 | I7: 0.825 | K7: 202010 | L7: 52 | M7: 10 | N7: 0.19230769 | O7: 0 | P7: 0 | Q7: 42 | R7: 0.80769231
B9: Indicador institucional - 1d. Retiro temprano % de retiro de las cohortes con 3 semestres de estudio calculado en una ventana de 1 año | K9: Indicador institucional - 3b. Retiro temprano 1, 2 y 3 % de retiro de las cohortes con 3 semestres de estudio calculado en una ventana de 1 año
B10: 2014 122-131 | C10: 2015 132-141 | D10: 2016 142-151 | E10: 2017 152-161 | F10: 2018 162-171 | G10: 2019 172-181 | H10: **2020 182-191 | I10: 2021 192-201 | K10: 2014 122-131 | L10: 2015 132-141 | M10: 2016 142-151 | N10: 2017 152-161 | O10: 2018 162-171 | P10: 2019 172-181 | Q10: **2020 182-191 | R10: 2021 192-201
B11: - | C11: - | D11: - | E11: - | F11: - | G11: - | H11: =((C4*E4)+(C5*E5))/(C4+C5) -> 0.19727891 | I11: =((C6*E6)+(C7*E7))/(C6+C7) -> 0.19512927 | K11: - | L11: - | M11: - | N11: - | O11: - | P11: - | Q11: =((L4*N4)+(L5*N5))/(L4+L5) -> 0.11392405 | R11: =((L6*N6)+(L7*N7))/(L6+L7) -> 0.19512195
B12: ** la desagregación a nivel de escuelas se empieza a realizar desde el 2020-1, pues las escuelas nacieron en el 2019. | K12: ** la desagregación a nivel de escuelas se empieza a realizar desde el 2020-1, pues las escuelas nacieron en el 2019.
B13: La escuela de Economía contiene los programas de: Economía y Negocios Internacionales, Economía y Contaduría y Finanzas. | K13: La escuela de Economía contiene los programas de: Economía y Negocios Internacionales, Economía y Contaduría y Finanzas.

Sheet ADD
A1: Fecha de corte: grados 2024-2. | M1: Fecha de corte: grados 2024-2.
A3: RETIRO TEMPRANO ADD | M3: RETIRO TEMPRANO ADD-ESTRATOS 1, 2 Y 3
A5: Periodo de ingreso - Estudiante | B5: No. Estudiantes | C5: No. Retirados | D5: % Retiro | E5: No. Graduados | F5: % Graduados | G5: Est. Activos | H5: % Activos | M5: Periodo de ingreso - Estudiante | N5: No. Estudiantes | O5: No. Retirados | P5: % Retiro | Q5: No. Graduados | R5: % Graduados | S5: Est. Activos | T5: % Activos
A6: 201310 | B6: 27 | C6: 5 | D6: 0.18518519 | E6: 0 | F6: 0 | G6: 22 | H6: 0.81481481 | M6: 201310 | N6: 11 | O6: 0 | P6: 0 | Q6: 0 | R6: 0 | S6: 11 | T6: 1
A7: 201320 | B7: 36 | C7: 11 | D7: 0.30555556 | E7: 0 | F7: 0 | G7: 25 | H7: 0.69444444 | M7: 201320 | N7: 13 | O7: 2 | P7: 0.154 | Q7: 0 | R7: 0 | S7: 11 | T7: 0.846
A8: 201410 | B8: 28 | C8: 8 | D8: 0.286 | E8: 0 | F8: 0 | G8: 20 | H8: 0.714 | M8: 201410 | N8: 13 | O8: 2 | P8: 0.154 | Q8: 0 | R8: 0 | S8: 11 | T8: 0.846
A9: 201420 | B9: 51 | C9: 11 | D9: 0.216 | E9: 0 | F9: 0 | G9: 40 | H9: 0.784 | M9: 201420 | N9: 9 | O9: 0 | P9: 0 | Q9: 0 | R9: 0 | S9: 9 | T9: 1
A10: 201510 | B10: 39 | C10: 12 | D10: 0.308 | E10: 0 | F10: 0 | G10: 27 | H10: 0.692 | M10: 201510 | N10: 15 | O10: 5 | P10: 0.333 | Q10: 0 | R10: 0 | S10: 10 | T10: 0.667
A11: 201520 | B11: 61 | C11: 15 | D11: 0.24590164 | E11: 0 | F11: 0 | G11: 46 | H11: 0.75409836 | M11: 201520 | N11: 13 | O11: 2 | P11: 0.15384615 | Q11: 0 | R11: 0 | S11: 11 | T11: 0.84615385
A12: 201610 | B12: 67 | C12: 19 | D12: 0.28358209 | E12: 0 | F12: 0 | G12: 48 | H12: 0.71641791 | M12: 201610 | N12: 32 | O12: 9 | P12: 0.28125 | Q12: 0 | R12: 0 | S12: 23 | T12: 0.71875
A13: 201620 | B13: 109 | C13: 30 | D13: 0.27522936 | E13: 0 | F13: 0 | G13: 79 | H13: 0.72477064 | M13: 201620 | N13: 34 | O13: 9 | P13: 0.26470588 | Q13: 0 | R13: 0 | S13: 25 | T13: 0.73529412
A14: 201710 | B14: 48 | C14: 9 | D14: 0.1875 | E14: 0 | F14: 0 | G14: 39 | H14: 0.8125 | M14: 201710 | N14: 28 | O14: 4 | P14: 0.14285714 | Q14: 0 | R14: 0 | S14: 24 | T14: 0.85714286
A15: 201720 | B15: 89 | C15: 19 | D15: 0.21348315 | E15: 0 | F15: 0 | G15: 70 | H15: 0.78651685 | M15: 201720 | N15: 24 | O15: 3 | P15: 0.125 | Q15: 0 | R15: 0 | S15: 21 | T15: 0.875
A16: 201810 | B16: 74 | C16: 22 | D16: 0.2972973 | E16: 0 | F16: 0 | G16: 52 | H16: 0.7027027 | M16: 201810 | N16: 28 | O16: 7 | P16: 0.25 | Q16: 0 | R16: 0 | S16: 21 | T16: 0.75
A17: 201820 | B17: 75 | C17: 15 | D17: 0.2 | E17: 0 | F17: 0 | G17: 60 | H17: 0.8 | M17: 201820 | N17: 25 | O17: 6 | P17: 0.24 | Q17: 0 | R17: 0 | S17: 19 | T17: 0.76
... A23: 202120 | B23: 38 | C23: 9 | D23: 0.23684211 | E23: 0 | F23: 0 | G23: 29 | H23: 0.76315789 | M23: 202120 | N23: 16 | O23: 4 | P23: 0.25 | Q23: 0 | R23: 0 | S23: 12 | T23: 0.75
A24: 202210 | B24: {=IF(RIGHT($A24,2)="10",_xlfn.XLOOKUP("ADD"&$A24,[1]PROGRAMA!$A:$A&[1]PROGRAMA!$B:$B,[1]PROGRAMA!C:C,0),_xlfn.XLOOKUP("ADD"&$A24,[2]PROGRAMA!$A:$A&[2]PROGRAMA!$B:$B,[2]PROGRAMA!C:C,0))} -> 64 | C24: {=IF(RIGHT($A24,2)="10",_xlfn.XLOOKUP("ADD"&$A24,[1]PROGRAMA!$A:$A&[1]PROGRAMA!$B:$B,[1]PROGRAMA!D:D,0),_xlfn.XLOOKUP("ADD"&$A24,[2]PROGRAMA!$A:$A&[2]PROGRAMA!$B:$B,[2]PROGRAMA!D:D,0))} -> 18 | D24: =IFERROR(C24/$B24,0) -> 0.28125 | E24: {=IF(RIGHT($A24,2)="10",_xlfn.XLOOKUP("ADD"&$A24,[1]PROGRAMA!$A:$A&[1]PROGRAMA!$B:$B,[1]PROGRAMA!E:E,0),_xlfn.XLOOKUP("ADD"&$A24,[2]PROGRAMA!$A:$A&[2]PROGRAMA!$B:$B,[2]PROGRAMA!E:E,0))} -> 0 | F24: =IFERROR(E24/$B24,0) -> 0 | G24: =B24-C24 -> 46 | H24: =IFERROR(G24/$B24,0) -> 0.71875 | M24: 202210 | N24: {=IF(RIGHT($A24,2)="10",_xlfn.XLOOKUP("ADD"&$A24,'[1]PROGRAMA 123'!$A:$A&'[1]PROGRAMA 123'!$B:$B,'[1]PROGRAMA 123'!C:C,0),_xlfn.XLOOKUP("ADD"&$A24,'[2]PROGRAMA 123'!$A:$A&'[2]PROGRAMA 123'!$B:$B,'[2]PROGRAMA 123'!C:C,0))} -> 33 | O24: {=IF(RIGHT($A24,2)="10",_xlfn.XLOOKUP("ADD"&$A24,'[1]PROGRAMA 123'!$A:$A&'[1]PROGRAMA 123'!$B:$B,'[1]PROGRAMA 123'!D:D,0),_xlfn.XLOOKUP("ADD"&$A24,'[2]PROGRAMA 123'!$A:$A&'[2]PROGRAMA 123'!$B:$B,'[2]PROGRAMA 123'!D:D,0))} -> 10 | P24: =IFERROR(O24/$N24,0) -> 0.3030303 | Q24: {=IF(RIGHT($A24,2)="10",_xlfn.XLOOKUP("ADD"&$A24,'[1]PROGRAMA 123'!$A:$A&'[1]PROGRAMA 123'!$B:$B,'[1]PROGRAMA 123'!E:E,0),_xlfn.XLOOKUP("ADD"&$A24,'[2]PROGRAMA 123'!$A:$A&'[2]PROGRAMA 123'!$B:$B,'[2]PROGRAMA 123'!E:E,0))} -> 0 | R24: =IFERROR(Q24/$N24,0) -> 0 | S24: =N24-O24 -> 23 | T24: =IFERROR(S24/$N24,0) -> 0.6969697
A25: 202220 | B25: {=IF(RIGHT($A25,2)="10",_xlfn.XLOOKUP("ADD"&$A25,[1]PROGRAMA!$A:$A&[1]PROGRAMA!$B:$B,[1]PROGRAMA!C:C,0),_xlfn.XLOOKUP("ADD"&$A25,[2]PROGRAMA!$A:$A&[2]PROGRAMA!$B:$B,[2]PROGRAMA!C:C,0))} -> 40 | C25: {=IF(RIGHT($A25,2)="10",_xlfn.XLOOKUP("ADD"&$A25,[1]PROGRAMA!$A:$A&[1]PROGRAMA!$B:$B,[1]PROGRAMA!D:D,0),_xlfn.XLOOKUP("ADD"&$A25,[2]PROGRAMA!$A:$A&[2]PROGRAMA!$B:$B,[2]PROGRAMA!D:D,0))} -> 11 | D25: =IFERROR(C25/$B25,0) -> 0.275 | E25: {=IF(RIGHT($A25,2)="10",_xlfn.XLOOKUP("ADD"&$A25,[1]PROGRAMA!$A:$A&[1]PROGRAMA!$B:$B,[1]PROGRAMA!E:E,0),_xlfn.XLOOKUP("ADD"&$A25,[2]PROGRAMA!$A:$A&[2]PROGRAMA!$B:$B,[2]PROGRAMA!E:E,0))} -> 0 | F25: =IFERROR(E25/$B25,0) -> 0 | G25: =B25-C25 -> 29 | H25: =IFERROR(G25/$B25,0) -> 0.725 | M25: 202220 | N25: {=IF(RIGHT($A25,2)="10",_xlfn.XLOOKUP("ADD"&$A25,'[1]PROGRAMA 123'!$A:$A&'[1]PROGRAMA 123'!$B:$B,'[1]PROGRAMA 123'!C:C,0),_xlfn.XLOOKUP("ADD"&$A25,'[2]PROGRAMA 123'!$A:$A&'[2]PROGRAMA 123'!$B:$B,'[2]PROGRAMA 123'!C:C,0))} -> 18 | O25: {=IF(RIGHT($A25,2)="10",_xlfn.XLOOKUP("ADD"&$A25,'[1]PROGRAMA 123'!$A:$A&'[1]PROGRAMA 123'!$B:$B,'[1]PROGRAMA 123'!D:D,0),_xlfn.XLOOKUP("ADD"&$A25,'[2]PROGRAMA 123'!$A:$A&'[2]PROGRAMA 123'!$B:$B,'[2]PROGRAMA 123'!D:D,0))} -> 3 | P25: =IFERROR(O25/$N25,0) -> 0.16666667 | Q25: {=IF(RIGHT($A25,2)="10",_xlfn.XLOOKUP("ADD"&$A25,'[1]PROGRAMA 123'!$A:$A&'[1]PROGRAMA 123'!$B:$B,'[1]PROGRAMA 123'!E:E,0),_xlfn.XLOOKUP("ADD"&$A25,'[2]PROGRAMA 123'!$A:$A&'[2]PROGRAMA 123'!$B:$B,'[2]PROGRAMA 123'!E:E,0))} -> 0 | R25: =IFERROR(Q25/$N25,0) -> 0 | S25: =N25-O25 -> 15 | T25: =IFERROR(S25/$N25,0) -> 0.83333333
A26: 202310 | B26: 41 | C26: 8 | D26: 0.19512195 | E26: 0 | F26: 0 | G26: 33 | H26: 0.80487805 | M26: 202310 | N26: 24 | O26: 5 | P26: 0.20833333 | Q26: 0 | R26: 0 | S26: 19 | T26: 0.79166667
A28: Indicador institucional - 1d. Retiro temprano % de retiro de las cohortes con 3 semestres de estudio calculado en una ventana de 1 año | M28: Indicador institucional - 3b. Retiro temprano 1, 2 y 3 % de retiro de las cohortes con 3 semestres de estudio calculado en una ventana de 1 año
A29: *2014 122-131 | B29: 2015 132-141 | C29: 2016 142-151 | D29: 2017 152-161 | E29: 2018 162-171 | F29: 2019 172-181 | G29: 2020 182-191 | H29: 2021 192-201 | I29: 2022 202-211 | J29: ='1d. Retiro temprano.'!K30 -> 2023 212-221 | K29: ='1d. Retiro temprano.'!L30 -> 2024-1*** 222 | M29: *2014 122-131 | N29: 2015 132-141 | O29: 2016 142-151 | P29: 2017 152-161 | Q29: 2018 162-171 | R29: 2019 172-181 | S29: 2020 182-191 | T29: 2021 192-201 | U29: 2022 202-211 | V29: =J29 -> 2023 212-221 | W29: =K29 -> 2024-1*** 222
A30: =D6 -> 0.18518519 | B30: =+((B7*D7)+(B8*D8))/(B7+B8) -> 0.297 | C30: =((B9*D9)+(B10*D10))/(B9+B10) -> 0.25586667 | D30: =+((B11*D11)+(B12*D12))/(B11+B12) -> 0.265625 | E30: =((B13*D13)+(B14*D14))/(B13+B14) -> 0.24840764 | F30: =((B15*D15)+(B16*D16))/(B15+B16) -> 0.25153374 | G30: =((B17*D17)+(B18*D18))/(B17+B18) -> 0.2231405 | H30: =((B19*D19)+(B20*D20))/(B19+B20) -> 0.13861386 | I30: =((B21*D21)+(B22*D22))/(B21+B22) -> 0.14285714 | J30: =(C23+C24)/(B23+B24) -> 0.26470588 | K30: =D25 -> 0.275 | M30: =P6 -> 0 | N30: =+((N7*P7)+(N8*P8))/(N7+N8) -> 0.154 | O30: =((N9*P9)+(N10*P10))/(N9+N10) -> 0.208125 | P30: =+((N11*P11)+(N12*P12))/(N11+N12) -> 0.24444444 | Q30: =((N13*P13)+(N14*P14))/(N13+N14) -> 0.20967742 | R30: =((N15*P15)+(N16*P16))/(N15+N16) -> 0.19230769 | S30: =((N17*P17)+(N18*P18))/(N17+N18) -> 0.21428571 | T30: =((N19*P19)+(N20*P20))/(N19+N20) -> 0.12 | U30: =((N21*P21)+(N22*P22))/(N21+N22) -> 0.041666667 | V30: =(O23+O24)/(N23+N24) -> 0.28571429 | W30: =P25 -> 0.16666667
A31: * para el año 2014 solo se tomó el porcentaje de retiro del periodo 131 porque no se contaba con el porcentaje del periodo 122 | M31: * para el año 2014 solo se tomó el porcentaje de retiro del periodo 131 porque no se contaba con el porcentaje del periodo 122
A32: ** Para el periodo 2024-1 sólo se tomo el procentaje de 202220 que a esa fecha de medición cumple 3 semestres de estudio cursado y están en su cuarto semestre. | M32: ** Para el periodo 2024-1 sólo se tomo el procentaje de 202220 que a esa fecha de medición cumple 3 semestres de estudio cursado y están en su cuarto semestre.

Sheet ANT
A1: Fecha de corte: grados 2024-2. | M1: Fecha de corte: grados 2024-2.
A3: RETIRO TEMPRANO ANT | M3: RETIRO TEMPRANO ANT-ESTRATOS 1, 2 Y 3
A4: Periodo de ingreso - Estudiante | B4: No. Estudiantes al periodo de ingreso | C4: No. Retirados al iniciar el 4to semestre | D4: % Retiro al iniciar el 4to semestre | E4: No. Graduados al iniciar el 4to semestre | F4: % Graduados al iniciar el 4to semestre | G4: Est. Activos al iniciar 4to semestre | H4: % Activos de estudiantes activos al iniciar 4to semestre | M4: Periodo de ingreso - Estudiante | N4: No. Estudiantes al periodo de ingreso | O4: No. Retirados al iniciar el 4to semestre | P4: % Retiro al iniciar el 4to semestre | Q4: No. Graduados al iniciar el 4to semestre | R4: % Graduados al iniciar el 4to semestre | S4: Est. Activos al iniciar 4to semestre | T4: % Activos de estudiantes activos al iniciar 4to semestre
A5: 201310 | B5: 5 | C5: 1 | D5: 0.2 | E5: 0 | F5: 0 | G5: 4 | H5: 0.8 | M5: 201310 | N5: 2 | O5: 0 | P5: 0 | Q5: 0 | R5: 0 | S5: 2 | T5: 1
A6: 201320 | B6: 13 | C6: 5 | D6: 0.38461538 | E6: 0 | F6: 0 | G6: 8 | H6: 0.61538462 | M6: 201320 | N6: 6 | O6: 2 | P6: 0.33333333 | Q6: 0 | R6: 0 | S6: 4 | T6: 0.66666667
A7: 201410 | B7: 7 | C7: 0 | D7: 0 | E7: 0 | F7: 0 | G7: 7 | H7: 1 | M7: 201410 | N7: 5 | O7: 0 | P7: 0 | Q7: 0 | R7: 0 | S7: 5 | T7: 1
A8: 201420 | B8: 7 | C8: 1 | D8: 0.143 | E8: 0 | F8: 0 | G8: 6 | H8: 0.857 | M8: 201420 | N8: 4 | O8: 1 | P8: 0.25 | Q8: 0 | R8: 0 | S8: 3 | T8: 0.75
A9: 201510 | B9: 4 | C9: 1 | D9: 0.25 | E9: 0 | F9: 0 | G9: 3 | H9: 0.75 | M9: 201510 | N9: 1 | O9: 0 | P9: 0 | Q9: 0 | R9: 0 | S9: 1 | T9: 1
A10: 201520 | B10: 6 | C10: 4 | D10: 0.66666667 | E10: 0 | F10: 0 | G10: 2 | H10: 0.33333333 | M10: 201520 | N10: 2 | O10: 1 | P10: 0.5 | Q10: 0 | R10: 0 | S10: 1 | T10: 0.5
A11: 201610 | B11: 6 | C11: 0 | D11: 0 | E11: 0 | F11: 0 | G11: 6 | H11: 1 | M11: 201610 | N11: 6 | O11: 0 | P11: 0 | Q11: 0 | R11: 0 | S11: 6 | T11: 1
A12: 201620 | B12: 7 | C12: 1 | D12: 0.14285714 | E12: 0 | F12: 0 | G12: 6 | H12: 0.85714286 | M12: 201620 | N12: 3 | O12: 1 | P12: 0.33333333 | Q12: 0 | R12: 0 | S12: 2 | T12: 0.66666667
A13: 201710 | B13: 15 | C13: 4 | D13: 0.26666667 | E13: 0 | F13: 0 | G13: 11 | H13: 0.73333333 | M13: 201710 | N13: 6 | O13: 2 | P13: 0.33333333 | Q13: 0 | R13: 0 | S13: 4 | T13: 0.66666667
A14: 201720 | B14: 10 | C14: 2 | D14: 0.2 | E14: 0 | F14: 0 | G14: 8 | H14: 0.8 | M14: 201720 | N14: 5 | O14: 1 | P14: 0.2 | Q14: 0 | R14: 0 | S14: 4 | T14: 0.8
A15: 201810 | B15: 10 | C15: 4 | D15: 0.4 | E15: 0 | F15: 0 | G15: 6 | H15: 0.6 | M15: 201810 | N15: 6 | O15: 2 | P15: 0.33333333 | Q15: 0 | R15: 0 | S15: 4 | T15: 0.66666667
A16: 201820 | B16: 9 | C16: 1 | D16: 0.11111111 | E16: 0 | F16: 0 | G16: 8 | H16: 0.88888889 | M16: 201820 | N16: 3 | O16: 1 | P16: 0.33333333 | Q16: 0 | R16: 0 | S16: 2 | T16: 0.66666667
A17: 201910 | B17: 10 | C17: 2 | D17: 0.2 | E17: 0 | F17: 0 | G17: 8 | H17: 0.8 | M17: 201910 | N17: 3 | O17: 1 | P17: 0.33333333 | Q17: 0 | R17: 0 | S17: 2 | T17: 0.66666667
A18: 201920 | B18: - | C18: - | D18: - | E18: - | F18: - | G18: - | H18: - | M18: 201920 | N18: - | O18: - | P18: - | Q18: - | R18: - | S18: - | T18: -
A19: 202010 | B19: 2 | C19: 1 | D19: 0.5 | E19: 0 | F19: 0 | G19: 1 | H19: 0.75 | M19: 202010 | N19: 1 | O19: 1 | P19: 1 | Q19: 0 | R19: 0 | S19: 0 | T19: 0
A20: 202020 | B20: 30 | C20: 4 | D20: 0.13333333 | E20: 0 | F20: 0 | G20: 26 | H20: 0.86666667 | M20: 202020 | N20: 13 | O20: 1 | P20: 0.076923077 | Q20: 0 | R20: 0 | S20: 12 | T20: 0.92307692
A21: 202110 | B21: 7 | C21: 2 | D21: 0.28571429 | E21: 0 | F21: 0 | G21: 5 | H21: 0.71428571 | M21: 202110 | N21: 3 | O21: 1 | P21: 0.33333333 | Q21: 0 | R21: 0 | S21: 2 | T21: 0.66666667
A22: 202120 | B22: 5 | C22: 3 | D22: 0.6 | E22: 0 | F22: 0 | G22: 2 | H22: 0.4 | M22: 202120 | N22: 2 | O22: 1 | P22: 0.5 | Q22: 0 | R22: 0 | S22: 1 | T22: 0.5
A23: 202210 | B23: {=IF(RIGHT($A23,2)="10",_xlfn.XLOOKUP("ANT"&$A23,[1]PROGRAMA!$A:$A&[1]PROGRAMA!$B:$B,[1]PROGRAMA!C:C,0),_xlfn.XLOOKUP("ANT"&$A23,[2]PROGRAMA!$A:$A&[2]PROGRAMA!$B:$B,[2]PROGRAMA!C:C,0))} -> 12 | C23: {=IF(RIGHT($A23,2)="10",_xlfn.XLOOKUP("ANT"&$A23,[1]PROGRAMA!$A:$A&[1]PROGRAMA!$B:$B,[1]PROGRAMA!D:D,0),_xlfn.XLOOKUP("ANT"&$A23,[2]PROGRAMA!$A:$A&[2]PROGRAMA!$B:$B,[2]PROGRAMA!D:D,0))} -> 2 | D23: =IFERROR(C23/$B23,0) -> 0.16666667 | E23: {=IF(RIGHT($A23,2)="10",_xlfn.XLOOKUP("ANT"&$A23,[1]PROGRAMA!$A:$A&[1]PROGRAMA!$B:$B,[1]PROGRAMA!E:E,0),_xlfn.XLOOKUP("ANT"&$A23,[2]PROGRAMA!$A:$A&[2]PROGRAMA!$B:$B,[2]PROGRAMA!E:E,0))} -> 0 | F23: =IFERROR(E23/$B23,0) -> 0 | G23: =B23-C23 -> 10 | H23: =IFERROR(G23/$B23,0) -> 0.83333333 | M23: 202210 | N23: {=IF(RIGHT($A23,2)="10",_xlfn.XLOOKUP("ANT"&$A23,'[1]PROGRAMA 123'!$A:$A&'[1]PROGRAMA 123'!$B:$B,'[1]PROGRAMA 123'!C:C,0),_xlfn.XLOOKUP("ANT"&$A23,'[2]PROGRAMA 123'!$A:$A&'[2]PROGRAMA 123'!$B:$B,'[2]PROGRAMA 123'!C:C,0))} -> 10 | O23: {=IF(RIGHT($A23,2)="10",_xlfn.XLOOKUP("ANT"&$A23,'[1]PROGRAMA 123'!$A:$A&'[1]PROGRAMA 123'!$B:$B,'[1]PROGRAMA 123'!D:D,0),_xlfn.XLOOKUP("ANT"&$A23,'[2]PROGRAMA 123'!$A:$A&'[2]PROGRAMA 123'!$B:$B,'[2]PROGRAMA 123'!D:D,0))} -> 1 | P23: =IFERROR(O23/$N23,0) -> 0.1 | Q23: {=IF(RIGHT($A23,2)="10",_xlfn.XLOOKUP("ANT"&$A23,'[1]PROGRAMA 123'!$A:$A&'[1]PROGRAMA 123'!$B:$B,'[1]PROGRAMA 123'!E:E,0),_xlfn.XLOOKUP("ANT"&$A23,'[2]PROGRAMA 123'!$A:$A&'[2]PROGRAMA 123'!$B:$B,'[2]PROGRAMA 123'!E:E,0))} -> 0 | R23: =IFERROR(Q23/$N23,0) -> 0 | S23: =N23-O23 -> 9 | T23: =IFERROR(S23/$N23,0) -> 0.9
A24: 202220 | B24: {=IF(RIGHT($A24,2)="10",_xlfn.XLOOKUP("ANT"&$A24,[1]PROGRAMA!$A:$A&[1]PROGRAMA!$B:$B,[1]PROGRAMA!C:C,0),_xlfn.XLOOKUP("ANT"&$A24,[2]PROGRAMA!$A:$A&[2]PROGRAMA!$B:$B,[2]PROGRAMA!C:C,0))} -> 5 | C24: {=IF(RIGHT($A24,2)="10",_xlfn.XLOOKUP("ANT"&$A24,[1]PROGRAMA!$A:$A&[1]PROGRAMA!$B:$B,[1]PROGRAMA!D:D,0),_xlfn.XLOOKUP("ANT"&$A24,[2]PROGRAMA!$A:$A&[2]PROGRAMA!$B:$B,[2]PROGRAMA!D:D,0))} -> 1 | D24: =IFERROR(C24/$B24,0) -> 0.2 | E24: {=IF(RIGHT($A24,2)="10",_xlfn.XLOOKUP("ANT"&$A24,[1]PROGRAMA!$A:$A&[1]PROGRAMA!$B:$B,[1]PROGRAMA!E:E,0),_xlfn.XLOOKUP("ANT"&$A24,[2]PROGRAMA!$A:$A&[2]PROGRAMA!$B:$B,[2]PROGRAMA!E:E,0))} -> 0 | F24: =IFERROR(E24/$B24,0) -> 0 | G24: =B24-C24 -> 4 | H24: =IFERROR(G24/$B24,0) -> 0.8 | M24: 202220 | N24: {=IF(RIGHT($A24,2)="10",_xlfn.XLOOKUP("ANT"&$A24,'[1]PROGRAMA 123'!$A:$A&'[1]PROGRAMA 123'!$B:$B,'[1]PROGRAMA 123'!C:C,0),_xlfn.XLOOKUP("ANT"&$A24,'[2]PROGRAMA 123'!$A:$A&'[2]PROGRAMA 123'!$B:$B,'[2]PROGRAMA 123'!C:C,0))} -> 2 | O24: {=IF(RIGHT($A24,2)="10",_xlfn.XLOOKUP("ANT"&$A24,'[1]PROGRAMA 123'!$A:$A&'[1]PROGRAMA 123'!$B:$B,'[1]PROGRAMA 123'!D:D,0),_xlfn.XLOOKUP("ANT"&$A24,'[2]PROGRAMA 123'!$A:$A&'[2]PROGRAMA 123'!$B:$B,'[2]PROGRAMA 123'!D:D,0))} -> 0 | P24: =IFERROR(O24/$N24,0) -> 0 | Q24: {=IF(RIGHT($A24,2)="10",_xlfn.XLOOKUP("ANT"&$A24,'[1]PROGRAMA 123'!$A:$A&'[1]PROGRAMA 123'!$B:$B,'[1]PROGRAMA 123'!E:E,0),_xlfn.XLOOKUP("ANT"&$A24,'[2]PROGRAMA 123'!$A:$A&'[2]PROGRAMA 123'!$B:$B,'[2]PROGRAMA 123'!E:E,0))} -> 0 | R24: =IFERROR(Q24/$N24,0) -> 0 | S24: =N24-O24 -> 2 | T24: =IFERROR(S24/$N24,0) -> 1
A25: 202310 | B25: 15 | C25: 1 | D25: =IFERROR(C25/$B25,0) -> 0.066666667 | E25: 0 | F25: =IFERROR(E25/$B25,0) -> 0 | G25: 14 | H25: =IFERROR(G25/$B25,0) -> 0.93333333 | M25: 202310 | N25: 10 | O25: 0 | P25: =IFERROR(O25/$N25,0) -> 0 | Q25: 0 | R25: =IFERROR(Q25/$N25,0) -> 0 | S25: 10 | T25: =IFERROR(S25/$N25,0) -> 1
A27: Indicador institucional - 1d. Retiro temprano % de retiro de las cohortes con 3 semestres de estudio calculado en una ventana de 1 año | M27: Indicador institucional - 3b. Retiro temprano 1, 2 y 3 % de retiro de las cohortes con 3 semestres de estudio calculado en una ventana de 1 año
A28: *2014 122-131 | B28: 2015 132-141 | C28: 2016 142-151 | D28: 2017 152-161 | E28: 2018 162-171 | F28: 2019 172-181 | G28: 2020 182-191 | H28: 2021 192-201 | I28: 2022 202-211 | J28: ='1d. Retiro temprano.'!K30 -> 2023 212-221 | K28: ='1d. Retiro temprano.'!L30 -> 2024-1*** 222 | M28: **2014 122-131 | N28: 2015 132-141 | O28: 2016 142-151 | P28: 2017 152-161 | Q28: 2018 162-171 | R28: 2019 172-181 | S28: 2020 182-191 | T28: 2021 192-201 | U28: 2022 202-211 | V28: =J28 -> 2023 212-221 | W28: =K28 -> 2024-1*** 222
A29: =D5 -> 0.2 | B29: =+((B6*D6)+(B7*D7))/(B6+B7) -> 0.25 | C29: =((B8*D8)+(B9*D9))/(B8+B9) -> 0.18190909 | D29: =+((B10*D10)+(B11*D11))/(B10+B11) -> 0.33333333 | E29: =((B12*D12)+(B13*D13))/(B12+B13) -> 0.22727273 | F29: =((B14*D14)+(B15*D15))/(B14+B15) -> 0.3 | G29: =((B16*D16)+(B17*D17))/(B16+B17) -> 0.15789474 | H29: =D19 -> 0.5 | I29: =((B20*D20)+(B21*D21))/(B20+B21) -> 0.16216216 | J29: =(C22+C23)/(B22+B23) -> 0.29411765 | K29: =D24 -> 0.2 | M29: =P5 -> 0 | N29: =+((N6*P6)+(N7*P7))/(N6+N7) -> 0.18181818 | O29: =((N8*P8)+(N9*P9))/(N8+N9) -> 0.2 | P29: =+((N10*P10)+(N11*P11))/(N10+N11) -> 0.125 | Q29: =((N12*P12)+(N13*P13))/(N12+N13) -> 0.33333333 | R29: =((N14*P14)+(N15*P15))/(N14+N15) -> 0.27272727 | S29: =((N16*P16)+(N17*P17))/(N16+N17) -> 0.33333333 | T29: =P19 -> 1 | U29: =((N20*P20)+(N21*P21))/(N20+N21) -> 0.125 | V29: =(O22+O23)/(N22+N23) -> 0.16666667 | W29: =P24 -> 0
A30: * para el año 2014 solo se tomó el porcentaje de retiro del periodo 131 porque no se contaba con el porcentaje del periodo 122 | M30: * para el año 2014 solo se tomó el porcentaje de retiro del periodo 131 porque no se contaba con el porcentaje del periodo 122
A31: ** Para el periodo 2024-1 sólo se tomo el procentaje de 202220 que a esa fecha de medición cumple 3 semestres de estudio cursado y están en su cuarto semestre. | M31: ** Para el periodo 2024-1 sólo se tomo el procentaje de 202220 que a esa fecha de medición cumple 3 semestres de estudio cursado y están en su cuarto semestre.

Sheet ECO
A1: Fecha de corte: grados 2024-2. | M1: Fecha de corte: grados 2024-2.
A3: RETIRO TEMPRANO ECO | M3: RETIRO TEMPRANO ECO-ESTRATOS 1, 2 Y 3
A5: Periodo de ingreso - Estudiante | B5: No. Estudiantes | C5: No. Retirados | D5: % Retiro | E5: No. Graduados | F5: % Graduados | G5: Est. Activos | H5: % Activos | M5: Periodo de ingreso - Estudiante | N5: No. Estudiantes | O5: No. Retirados | P5: % Retiro | Q5: No. Graduados | R5: % Graduados | S5: Est. Activos | T5: % Activos
A6: 201310 | B6: - | C6: - | D6: - | E6: - | F6: - | G6: - | H6: - | M6: 201310 | N6: - | O6: - | P6: - | Q6: - | R6: - | S6: - | T6: -
A7: 201320 | B7: 9 | C7: 2 | D7: 0.22222222 | E7: 0 | F7: 0 | G7: 7 | H7: 0.77777778 | M7: 201320 | N7: 3 | O7: 0 | P7: 0 | Q7: 0 | R7: 0 | S7: 3 | T7: 1
A8: 201410 | B8: 2 | C8: 2 | D8: 1 | E8: 0 | F8: 0 | G8: 0 | H8: 0 | M8: 201410 | N8: 2 | O8: 2 | P8: 1 | Q8: 0 | R8: 0 | S8: 0 | T8: 0
A9: 201420 | B9: 7 | C9: 1 | D9: 0.143 | E9: 0 | F9: 0 | G9: 6 | H9: 0.857 | M9: 201420 | N9: 2 | O9: 1 | P9: 0.5 | Q9: 0 | R9: 0 | S9: 1 | T9: 0.5
A10: 201510 | B10: 11 | C10: 4 | D10: 0.364 | E10: 0 | F10: 0 | G10: 7 | H10: 0.636 | M10: 201510 | N10: 9 | O10: 3 | P10: 0.333 | Q10: 0 | R10: 0 | S10: 6 | T10: 0.667
A11: 201520 | B11: 4 | C11: 1 | D11: 0.25 | E11: 0 | F11: 0 | G11: 3 | H11: 0.75 | M11: 201520 | N11: 2 | O11: 0 | P11: 0 | Q11: 0 | R11: 0 | S11: 2 | T11: 1
A12: 201610 | B12: 11 | C12: 4 | D12: 0.36363636 | E12: 0 | F12: 0 | G12: 7 | H12: 0.63636364 | M12: 201610 | N12: 9 | O12: 4 | P12: 0.44444444 | Q12: 0 | R12: 0 | S12: 5 | T12: 0.55555556
A13: 201620 | B13: 10 | C13: 2 | D13: 0.2 | E13: 0 | F13: 0 | G13: 8 | H13: 0.8 | M13: 201620 | N13: 7 | O13: 1 | P13: 0.14285714 | Q13: 0 | R13: 0 | S13: 6 | T13: 0.85714286
A14: 201710 | B14: 7 | C14: 1 | D14: 0.14285714 | E14: 0 | F14: 0 | G14: 6 | H14: 0.85714286 | M14: 201710 | N14: 6 | O14: 1 | P14: 0.16666667 | Q14: 0 | R14: 0 | S14: 5 | T14: 0.83333333
A15: 201720 | B15: 8 | C15: 0 | D15: 0 | E15: 0 | F15: 0 | G15: 8 | H15: 1 | M15: 201720 | N15: 5 | O15: 0 | P15: 0 | Q15: 0 | R15: 0 | S15: 5 | T15: 1
A16: 201810 | B16: 5 | C16: 2 | D16: 0.4 | E16: 0 | F16: 0 | G16: 3 | H16: 0.6 | M16: 201810 | N16: 4 | O16: 2 | P16: 0.5 | Q16: 0 | R16: 0 | S16: 2 | T16: 0.5
A17: 201820 | B17: 7 | C17: 2 | D17: 0.28571429 | E17: 0 | F17: 0 | G17: 5 | H17: 0.71428571 | M17: 201820 | N17: 3 | O17: 1 | P17: 0.33333333 | Q17: 0 | R17: 0 | S17: 2 | T17: 0.66666667
A18: 201910 | B18: 5 | C18: 2 | D18: 0.4 | E18: 0 | F18: 0 | G18: 3 | H18: 0.6 | M18: 201910 | N18: 4 | O18: 1 | P18: 0.25 | Q18: 0 | R18: 0 | S18: 3 | T18: 0.75
... A23: 202120 | B23: 4 | C23: 1 | D23: 0.25 | E23: 0 | F23: 0 | G23: 3 | H23: 0.75 | M23: 202120 | N23: 1 | O23: 1 | P23: 1 | Q23: 0 | R23: 0 | S23: 0 | T23: 0
A24: 202210 | B24: {=IF(RIGHT($A24,2)="10",_xlfn.XLOOKUP("ECO"&$A24,[1]PROGRAMA!$A:$A&[1]PROGRAMA!$B:$B,[1]PROGRAMA!C:C,0),_xlfn.XLOOKUP("ECO"&$A24,[2]PROGRAMA!$A:$A&[2]PROGRAMA!$B:$B,[2]PROGRAMA!C:C,0))} -> 6 | C24: {=IF(RIGHT($A24,2)="10",_xlfn.XLOOKUP("ECO"&$A24,[1]PROGRAMA!$A:$A&[1]PROGRAMA!$B:$B,[1]PROGRAMA!D:D,0),_xlfn.XLOOKUP("ECO"&$A24,[2]PROGRAMA!$A:$A&[2]PROGRAMA!$B:$B,[2]PROGRAMA!D:D,0))} -> 0 | D24: =IFERROR(C24/$B24,0) -> 0 | E24: {=IF(RIGHT($A24,2)="10",_xlfn.XLOOKUP("ECO"&$A24,[1]PROGRAMA!$A:$A&[1]PROGRAMA!$B:$B,[1]PROGRAMA!E:E,0),_xlfn.XLOOKUP("ECO"&$A24,[2]PROGRAMA!$A:$A&[2]PROGRAMA!$B:$B,[2]PROGRAMA!E:E,0))} -> 0 | F24: =IFERROR(E24/$B24,0) -> 0 | G24: =B24-C24 -> 6 | H24: =IFERROR(G24/$B24,0) -> 1 | M24: 202210 | N24: {=IF(RIGHT($A24,2)="10",_xlfn.XLOOKUP("ECO"&$A24,'[1]PROGRAMA 123'!$A:$A&'[1]PROGRAMA 123'!$B:$B,'[1]PROGRAMA 123'!C:C,0),_xlfn.XLOOKUP("ECO"&$A24,'[2]PROGRAMA 123'!$A:$A&'[2]PROGRAMA 123'!$B:$B,'[2]PROGRAMA 123'!C:C,0))} -> 2 | O24: {=IF(RIGHT($A24,2)="10",_xlfn.XLOOKUP("ECO"&$A24,'[1]PROGRAMA 123'!$A:$A&'[1]PROGRAMA 123'!$B:$B,'[1]PROGRAMA 123'!D:D,0),_xlfn.XLOOKUP("ECO"&$A24,'[2]PROGRAMA 123'!$A:$A&'[2]PROGRAMA 123'!$B:$B,'[2]PROGRAMA 123'!D:D,0))} -> 0 | P24: =IFERROR(O24/$N24,0) -> 0 | Q24: {=IF(RIGHT($A24,2)="10",_xlfn.XLOOKUP("ECO"&$A24,'[1]PROGRAMA 123'!$A:$A&'[1]PROGRAMA 123'!$B:$B,'[1]PROGRAMA 123'!E:E,0),_xlfn.XLOOKUP("ECO"&$A24,'[2]PROGRAMA 123'!$A:$A&'[2]PROGRAMA 123'!$B:$B,'[2]PROGRAMA 123'!E:E,0))} -> 0 | R24: =IFERROR(Q24/$N24,0) -> 0 | S24: =N24-O24 -> 2 | T24: =IFERROR(S24/$N24,0) -> 1
A25: 202220 | B25: {=IF(RIGHT($A25,2)="10",_xlfn.XLOOKUP("ECO"&$A25,[1]PROGRAMA!$A:$A&[1]PROGRAMA!$B:$B,[1]PROGRAMA!C:C,0),_xlfn.XLOOKUP("ECO"&$A25,[2]PROGRAMA!$A:$A&[2]PROGRAMA!$B:$B,[2]PROGRAMA!C:C,0))} -> 6 | C25: {=IF(RIGHT($A25,2)="10",_xlfn.XLOOKUP("ECO"&$A25,[1]PROGRAMA!$A:$A&[1]PROGRAMA!$B:$B,[1]PROGRAMA!D:D,0),_xlfn.XLOOKUP("ECO"&$A25,[2]PROGRAMA!$A:$A&[2]PROGRAMA!$B:$B,[2]PROGRAMA!D:D,0))} -> 0 | D25: =IFERROR(C25/$B25,0) -> 0 | E25: {=IF(RIGHT($A25,2)="10",_xlfn.XLOOKUP("ECO"&$A25,[1]PROGRAMA!$A:$A&[1]PROGRAMA!$B:$B,[1]PROGRAMA!E:E,0),_xlfn.XLOOKUP("ECO"&$A25,[2]PROGRAMA!$A:$A&[2]PROGRAMA!$B:$B,[2]PROGRAMA!E:E,0))} -> 0 | F25: =IFERROR(E25/$B25,0) -> 0 | G25: =B25-C25 -> 6 | H25: =IFERROR(G25/$B25,0) -> 1 | M25: 202220 | N25: {=IF(RIGHT($A25,2)="10",_xlfn.XLOOKUP("ECO"&$A25,'[1]PROGRAMA 123'!$A:$A&'[1]PROGRAMA 123'!$B:$B,'[1]PROGRAMA 123'!C:C,0),_xlfn.XLOOKUP("ECO"&$A25,'[2]PROGRAMA 123'!$A:$A&'[2]PROGRAMA 123'!$B:$B,'[2]PROGRAMA 123'!C:C,0))} -> 3 | O25: {=IF(RIGHT($A25,2)="10",_xlfn.XLOOKUP("ECO"&$A25,'[1]PROGRAMA 123'!$A:$A&'[1]PROGRAMA 123'!$B:$B,'[1]PROGRAMA 123'!D:D,0),_xlfn.XLOOKUP("ECO"&$A25,'[2]PROGRAMA 123'!$A:$A&'[2]PROGRAMA 123'!$B:$B,'[2]PROGRAMA 123'!D:D,0))} -> 0 | P25: =IFERROR(O25/$N25,0) -> 0 | Q25: {=IF(RIGHT($A25,2)="10",_xlfn.XLOOKUP("ECO"&$A25,'[1]PROGRAMA 123'!$A:$A&'[1]PROGRAMA 123'!$B:$B,'[1]PROGRAMA 123'!E:E,0),_xlfn.XLOOKUP("ECO"&$A25,'[2]PROGRAMA 123'!$A:$A&'[2]PROGRAMA 123'!$B:$B,'[2]PROGRAMA 123'!E:E,0))} -> 0 | R25: =IFERROR(Q25/$N25,0) -> 0 | S25: =N25-O25 -> 3 | T25: =IFERROR(S25/$N25,0) -> 1
A26: 202310 | B26: 6 | C26: 1 | D26: =IFERROR(C26/$B26,0) -> 0.16666667 | E26: 0 | F26: =IFERROR(E26/$B26,0) -> 0 | G26: 5 | H26: =IFERROR(G26/$B26,0) -> 0.83333333 | M26: 202310 | N26: 1 | O26: 0 | P26: =IFERROR(O26/$N26,0) -> 0 | Q26: 0 | R26: =IFERROR(Q26/$N26,0) -> 0 | S26: 1 | T26: =IFERROR(S26/$N26,0) -> 1
A28: Indicador institucional - 1d. Retiro temprano % de retiro de las cohortes con 3 semestres de estudio calculado en una ventana de 1 año | M28: Indicador institucional - 3b. Retiro temprano 1, 2 y 3 % de retiro de las cohortes con 3 semestres de estudio calculado en una ventana de 1 año
A29: 2014 122-131 | B29: 2015 132-141 | C29: 2016 142-151 | D29: 2017 152-161 | E29: 2018 162-171 | F29: 2019 172-181 | G29: 2020 182-191 | H29: 2021 192-201 | I29: 2022 202-211 | J29: ='1d. Retiro temprano.'!K30 -> 2023 212-221 | K29: ='1d. Retiro temprano.'!L30 -> 2024-1*** 222 | M29: 2014 122-131 | N29: 2015 132-141 | O29: 2016 142-151 | P29: 2017 152-161 | Q29: 2018 162-171 | R29: 2019 172-181 | S29: 2020 182-191 | T29: 2021 192-201 | U29: 2022 202-211 | V29: =J29 -> 2023 212-221 | W29: =K29 -> 2024-1*** 222
A30: =D6 -> - | B30: =+((B7*D7)+(B8*D8))/(B7+B8) -> 0.36363636 | C30: =((B9*D9)+(B10*D10))/(B9+B10) -> 0.27805556 | D30: =+((B11*D11)+(B12*D12))/(B11+B12) -> 0.33333333 | E30: =((B13*D13)+(B14*D14))/(B13+B14) -> 0.17647059 | F30: =((B15*D15)+(B16*D16))/(B15+B16) -> 0.15384615 | G30: =((B17*D17)+(B18*D18))/(B17+B18) -> 0.33333333 | H30: =((B19*D19)+(B20*D20))/(B19+B20) -> 0.25 | I30: =((B21*D21)+(B22*D22))/(B21+B22) -> 0.25 | J30: =(C23+C24)/(B23+B24) -> 0.1 | K30: =D25 -> 0 | M30: =P6 -> - | N30: =+((N7*P7)+(N8*P8))/(N7+N8) -> 0.4 | O30: =((N9*P9)+(N10*P10))/(N9+N10) -> 0.36336364 | P30: =+((N11*P11)+(N12*P12))/(N11+N12) -> 0.36363636 | Q30: =((N13*P13)+(N14*P14))/(N13+N14) -> 0.15384615 | R30: =((N15*P15)+(N16*P16))/(N15+N16) -> 0.22222222 | S30: =((N17*P17)+(N18*P18))/(N17+N18) -> 0.28571429 | T30: =((N19*P19)+(N20*P20))/(N19+N20) -> 0.28571429 | U30: =((N21*P21)+(N22*P22))/(N21+N22) -> 0 | V30: =(O23+O24)/(N23+N24) -> 0.33333333 | W30: =P25 -> 0
A31: * Para el periodo 2024-1 sólo se tomo el procentaje de 202220 que a esa fecha de medición cumple 3 semestres de estudio cursado y están en su cuarto semestre. | M31: * Para el periodo 2024-1 sólo se tomo el procentaje de 202220 que a esa fecha de medición cumple 3 semestres de estudio cursado y están en su cuarto semestre.

Sheet ENI
A1: Fecha de corte: grados 2024-2. | M1: Fecha de corte: grados 2024-2.
A3: RETIRO TEMPRANO ENI | M3: RETIRO TEMPRANO ENI-ESTRATOS 1, 2 Y 3
A5: Periodo de ingreso - Estudiante | B5: No. Estudiantes | C5: No. Retirados | D5: % Retiro | E5: No. Graduados | F5: % Graduados | G5: Est. Activos | H5: % Activos | M5: Periodo de ingreso - Estudiante | N5: No. Estudiantes | O5: No. Retirados | P5: % Retiro | Q5: No. Graduados | R5: % Graduados | S5: Est. Activos | T5: % Activos
A6: 201310 | B6: 92 | C6: 31 | D6: 0.33695652 | E6: 0 | F6: 0 | G6: 61 | H6: 0.66304348 | M6: 201310 | N6: 67 | O6: 23 | P6: 0.34328358 | Q6: 0 | R6: 0 | S6: 44 | T6: 0.65671642
A7: 201320 | B7: 101 | C7: 30 | D7: 0.2970297 | E7: 0 | F7: 0 | G7: 71 | H7: 0.7029703 | M7: 201320 | N7: 46 | O7: 13 | P7: 0.2826087 | Q7: 0 | R7: 0 | S7: 33 | T7: 0.7173913
A8: 201410 | B8: 66 | C8: 21 | D8: 0.318 | E8: 0 | F8: 0 | G8: 45 | H8: 0.682 | M8: 201410 | N8: 43 | O8: 11 | P8: 0.256 | Q8: 0 | R8: 0 | S8: 32 | T8: 0.744
A9: 201420 | B9: 115 | C9: 41 | D9: 0.357 | E9: 0 | F9: 0 | G9: 74 | H9: 0.643 | M9: 201420 | N9: 49 | O9: 18 | P9: 0.367 | Q9: 0 | R9: 0 | S9: 31 | T9: 0.633
A10: 201510 | B10: 97 | C10: 29 | D10: 0.299 | E10: 0 | F10: 0 | G10: 68 | H10: 0.701 | M10: 201510 | N10: 80 | O10: 25 | P10: 0.313 | Q10: 0 | R10: 0 | S10: 55 | T10: 0.688
A11: 201520 | B11: 84 | C11: 18 | D11: 0.21428571 | E11: 0 | F11: 0 | G11: 66 | H11: 0.78571429 | M11: 201520 | N11: 40 | O11: 5 | P11: 0.125 | Q11: 0 | R11: 0 | S11: 35 | T11: 0.875
A12: 201610 | B12: 135 | C12: 37 | D12: 0.27407407 | E12: 0 | F12: 0 | G12: 98 | H12: 0.72592593 | M12: 201610 | N12: 101 | O12: 25 | P12: 0.24752475 | Q12: 0 | R12: 0 | S12: 76 | T12: 0.75247525
A13: 201620 | B13: 88 | C13: 23 | D13: 0.26136364 | E13: 0 | F13: 0 | G13: 65 | H13: 0.73863636 | M13: 201620 | N13: 37 | O13: 13 | P13: 0.35135135 | Q13: 0 | R13: 0 | S13: 24 | T13: 0.64864865
A14: 201710 | B14: 93 | C14: 28 | D14: 0.30107527 | E14: 0 | F14: 0 | G14: 65 | H14: 0.69892473 | M14: 201710 | N14: 70 | O14: 21 | P14: 0.3 | Q14: 0 | R14: 0 | S14: 49 | T14: 0.7
A15: 201720 | B15: 63 | C15: 15 | D15: 0.23809524 | E15: 0 | F15: 0 | G15: 48 | H15: 0.76190476 | M15: 201720 | N15: 30 | O15: 7 | P15: 0.23333333 | Q15: 0 | R15: 0 | S15: 23 | T15: 0.76666667
A16: 201810 | B16: 60 | C16: 8 | D16: 0.13333333 | E16: 0 | F16: 0 | G16: 52 | H16: 0.86666667 | M16: 201810 | N16: 36 | O16: 7 | P16: 0.19444444 | Q16: 0 | R16: 0 | S16: 29 | T16: 0.80555556
A17: 201820 | B17: 50 | C17: 17 | D17: 0.34 | E17: 0 | F17: 0 | G17: 33 | H17: 0.66 | M17: 201820 | N17: 14 | O17: 5 | P17: 0.35714286 | Q17: 0 | R17: 0 | S17: 9 | T17: 0.64285714
... A23: 202120 | B23: 42 | C23: 10 | D23: 0.23809524 | E23: 0 | F23: 0 | G23: 32 | H23: 0.76190476 | M23: 202120 | N23: 22 | O23: 3 | P23: 0.13636364 | Q23: 0 | R23: 0 | S23: 19 | T23: 0.86363636
A24: 202210 | B24: {=IF(RIGHT($A24,2)="10",_xlfn.XLOOKUP("ENI"&$A24,[1]PROGRAMA!$A:$A&[1]PROGRAMA!$B:$B,[1]PROGRAMA!C:C,0),_xlfn.XLOOKUP("ENI"&$A24,[2]PROGRAMA!$A:$A&[2]PROGRAMA!$B:$B,[2]PROGRAMA!C:C,0))} -> 64 | C24: {=IF(RIGHT($A24,2)="10",_xlfn.XLOOKUP("ENI"&$A24,[1]PROGRAMA!$A:$A&[1]PROGRAMA!$B:$B,[1]PROGRAMA!D:D,0),_xlfn.XLOOKUP("ENI"&$A24,[2]PROGRAMA!$A:$A&[2]PROGRAMA!$B:$B,[2]PROGRAMA!D:D,0))} -> 14 | D24: =IFERROR(C24/$B24,0) -> 0.21875 | E24: {=IF(RIGHT($A24,2)="10",_xlfn.XLOOKUP("ENI"&$A24,[1]PROGRAMA!$A:$A&[1]PROGRAMA!$B:$B,[1]PROGRAMA!E:E,0),_xlfn.XLOOKUP("ENI"&$A24,[2]PROGRAMA!$A:$A&[2]PROGRAMA!$B:$B,[2]PROGRAMA!E:E,0))} -> 0 | F24: =IFERROR(E24/$B24,0) -> 0 | G24: =B24-C24 -> 50 | H24: =IFERROR(G24/$B24,0) -> 0.78125 | M24: 202210 | N24: {=IF(RIGHT($A24,2)="10",_xlfn.XLOOKUP("ENI"&$A24,'[1]PROGRAMA 123'!$A:$A&'[1]PROGRAMA 123'!$B:$B,'[1]PROGRAMA 123'!C:C,0),_xlfn.XLOOKUP("ENI"&$A24,'[2]PROGRAMA 123'!$A:$A&'[2]PROGRAMA 123'!$B:$B,'[2]PROGRAMA 123'!C:C,0))} -> 40 | O24: {=IF(RIGHT($A24,2)="10",_xlfn.XLOOKUP("ENI"&$A24,'[1]PROGRAMA 123'!$A:$A&'[1]PROGRAMA 123'!$B:$B,'[1]PROGRAMA 123'!D:D,0),_xlfn.XLOOKUP("ENI"&$A24,'[2]PROGRAMA 123'!$A:$A&'[2]PROGRAMA 123'!$B:$B,'[2]PROGRAMA 123'!D:D,0))} -> 6 | P24: =IFERROR(O24/$N24,0) -> 0.15 | Q24: {=IF(RIGHT($A24,2)="10",_xlfn.XLOOKUP("ENI"&$A24,'[1]PROGRAMA 123'!$A:$A&'[1]PROGRAMA 123'!$B:$B,'[1]PROGRAMA 123'!E:E,0),_xlfn.XLOOKUP("ENI"&$A24,'[2]PROGRAMA 123'!$A:$A&'[2]PROGRAMA 123'!$B:$B,'[2]PROGRAMA 123'!E:E,0))} -> 0 | R24: =IFERROR(Q24/$N24,0) -> 0 | S24: =N24-O24 -> 34 | T24: =IFERROR(S24/$N24,0) -> 0.85
A25: 202220 | B25: {=IF(RIGHT($A25,2)="10",_xlfn.XLOOKUP("ENI"&$A25,[1]PROGRAMA!$A:$A&[1]PROGRAMA!$B:$B,[1]PROGRAMA!C:C,0),_xlfn.XLOOKUP("ENI"&$A25,[2]PROGRAMA!$A:$A&[2]PROGRAMA!$B:$B,[2]PROGRAMA!C:C,0))} -> 59 | C25: {=IF(RIGHT($A25,2)="10",_xlfn.XLOOKUP("ENI"&$A25,[1]PROGRAMA!$A:$A&[1]PROGRAMA!$B:$B,[1]PROGRAMA!D:D,0),_xlfn.XLOOKUP("ENI"&$A25,[2]PROGRAMA!$A:$A&[2]PROGRAMA!$B:$B,[2]PROGRAMA!D:D,0))} -> 11 | D25: =IFERROR(C25/$B25,0) -> 0.18644068 | E25: {=IF(RIGHT($A25,2)="10",_xlfn.XLOOKUP("ENI"&$A25,[1]PROGRAMA!$A:$A&[1]PROGRAMA!$B:$B,[1]PROGRAMA!E:E,0),_xlfn.XLOOKUP("ENI"&$A25,[2]PROGRAMA!$A:$A&[2]PROGRAMA!$B:$B,[2]PROGRAMA!E:E,0))} -> 0 | F25: =IFERROR(E25/$B25,0) -> 0 | G25: =B25-C25 -> 48 | H25: =IFERROR(G25/$B25,0) -> 0.81355932 | M25: 202220 | N25: {=IF(RIGHT($A25,2)="10",_xlfn.XLOOKUP("ENI"&$A25,'[1]PROGRAMA 123'!$A:$A&'[1]PROGRAMA 123'!$B:$B,'[1]PROGRAMA 123'!C:C,0),_xlfn.XLOOKUP("ENI"&$A25,'[2]PROGRAMA 123'!$A:$A&'[2]PROGRAMA 123'!$B:$B,'[2]PROGRAMA 123'!C:C,0))} -> 43 | O25: {=IF(RIGHT($A25,2)="10",_xlfn.XLOOKUP("ENI"&$A25,'[1]PROGRAMA 123'!$A:$A&'[1]PROGRAMA 123'!$B:$B,'[1]PROGRAMA 123'!D:D,0),_xlfn.XLOOKUP("ENI"&$A25,'[2]PROGRAMA 123'!$A:$A&'[2]PROGRAMA 123'!$B:$B,'[2]PROGRAMA 123'!D:D,0))} -> 6 | P25: =IFERROR(O25/$N25,0) -> 0.13953488 | Q25: {=IF(RIGHT($A25,2)="10",_xlfn.XLOOKUP("ENI"&$A25,'[1]PROGRAMA 123'!$A:$A&'[1]PROGRAMA 123'!$B:$B,'[1]PROGRAMA 123'!E:E,0),_xlfn.XLOOKUP("ENI"&$A25,'[2]PROGRAMA 123'!$A:$A&'[2]PROGRAMA 123'!$B:$B,'[2]PROGRAMA 123'!E:E,0))} -> 0 | R25: =IFERROR(Q25/$N25,0) -> 0 | S25: =N25-O25 -> 37 | T25: =IFERROR(S25/$N25,0) -> 0.86046512
A26: 202310 | B26: 41 | C26: 5 | D26: =IFERROR(C26/$B26,0) -> 0.12195122 | E26: 0 | F26: =IFERROR(E26/$B26,0) -> 0 | G26: 36 | H26: =IFERROR(G26/$B26,0) -> 0.87804878 | M26: 202310 | N26: 30 | O26: 4 | P26: =IFERROR(O26/$N26,0) -> 0.13333333 | Q26: 0 | R26: =IFERROR(Q26/$N26,0) -> 0 | S26: 26 | T26: =IFERROR(S26/$N26,0) -> 0.86666667
A28: Indicador institucional - 1d. Retiro temprano % de retiro de las cohortes con 3 semestres de estudio calculado en una ventana de 1 año | M28: Indicador institucional - 3b. Retiro temprano 1, 2 y 3 % de retiro de las cohortes con 3 semestres de estudio calculado en una ventana de 1 año
A29: *2014 122-131 | B29: 2015 132-141 | C29: 2016 142-151 | D29: 2017 152-161 | E29: 2018 162-171 | F29: 2019 172-181 | G29: 2020 182-191 | H29: 2021 192-201 | I29: 2022 202-211 | J29: ='1d. Retiro temprano.'!K30 -> 2023 212-221 | K29: ='1d. Retiro temprano.'!L30 -> 2024-1*** 222 | M29: *2014 122-131 | N29: 2015 132-141 | O29: 2016 142-151 | P29: 2017 152-161 | Q29: 2018 162-171 | R29: 2019 172-181 | S29: 2020 182-191 | T29: 2021 192-201 | U29: 2022 202-211 | V29: =J29 -> 2023 212-221 | W29: =K29 -> 2024-1*** 222
